Workbook

Sheet README
A1: E196 reference-fix comparison
A2: 29 affected cases; formulas recalculate deltas and direction-aware improvements.
A4: Decision | B4: REFERENCE_FIX_VALIDATED_G1_IMPROVES | C4: Technical reference contract and corrected G1 performance are separate claims
A5: Scope | B5: 29 mismatch cases | C5: box001=21; box023=8 | D5: box001 primary excludes box001_20231023_110_p1
A6: Arms | B6: PRG | C6: G1 contaminated (E194) | D6: G1 corrected (E196)
A7: Delta | B7: Raw delta = candidate - baseline | C7: Improvement flips sign for lower-is-better metrics | D7: Positive improvement is always better
A8: Color | B8: Improvement >0 green | C8: Improvement =0 yellow | D8: Improvement <0 red
A9: Integrity | B9: 29/29 pass | C9: runtime/meta/XML parity | D9: target max <1e-4 deg
A10: CI | B10: 10,000 paired bootstrap draws | C10: seed fixed per row | D10: CI cells are evidence values; workbook means/deltas are formulas
A11: Sources | B11: e196_reference_fix_by_case.tsv | C11: e196_reference_integrity_audit.tsv | D11: e196_reference_fix_by_object.tsv

Sheet Paired Comparison
A1: Same-case paired comparison
A2: Raw Delta = candidate-baseline. Improvement is direction-aware; positive is always better.
A4: Comparison | B4: Baseline arm | C4: Candidate arm | D4: Case | E4: Object | F4: Box001 primary | G4: Metric key | H4: Metric | I4: Direction | J4: Baseline value | K4: Candidate value | L4: Raw Delta | M4: Improvement
A5: corrected_vs_prg | B5: PRG | C5: G1 corrected | D5: box001_20231003_2_041_p1 | E5: box001 | F5: =TRUE() -> TRUE | G5: track_obj_z_abs_err_cm_mean | H5: Object z MAE (cm) | I5: lower | J5: 6.7316664 | K5: 3.6141629 | L5: =K5-J5 -> -3.1175035 | M5: =IF(I5="higher",L5,-L5) -> 3.1175035
A6: corrected_vs_prg | B6: PRG | C6: G1 corrected | D6: box001_20231003_2_041_p1 | E6: box001 | F6: =TRUE() -> TRUE | G6: track_obj_pos_err_cm_mean | H6: Object 3D position error (cm) | I6: lower | J6: 11.546123 | K6: 9.9521637 | L6: =K6-J6 -> -1.5939598 | M6: =IF(I6="higher",L6,-L6) -> 1.5939598
A7: corrected_vs_prg | B7: PRG | C7: G1 corrected | D7: box001_20231003_2_041_p1 | E7: box001 | F7: =TRUE() -> TRUE | G7: track_obj_ori_err_deg_mean | H7: Object orientation error (deg) | I7: lower | J7: 7.6461315 | K7: 6.966659 | L7: =K7-J7 -> -0.67947254 | M7: =IF(I7="higher",L7,-L7) -> 0.67947254
A8: corrected_vs_prg | B8: PRG | C8: G1 corrected | D8: box001_20231003_2_041_p1 | E8: box001 | F8: =TRUE() -> TRUE | G8: body_z_err_p95_m | H8: Body z error p95 (m) | I8: lower | J8: 0.090091197 | K8: 0.065610757 | L8: =K8-J8 -> -0.02448044 | M8: =IF(I8="higher",L8,-L8) -> 0.02448044
A9: corrected_vs_prg | B9: PRG | C9: G1 corrected | D9: box001_20231003_2_041_p1 | E9: box001 | F9: =TRUE() -> TRUE | G9: track_root_pos_err_cm_mean | H9: Body/root position error (cm) | I9: lower | J9: 12.699191 | K9: 11.19642 | L9: =K9-J9 -> -1.5027718 | M9: =IF(I9="higher",L9,-L9) -> 1.5027718
A10: corrected_vs_prg | B10: PRG | C10: G1 corrected | D10: box001_20231003_2_041_p1 | E10: box001 | F10: =TRUE() -> TRUE | G10: track_root_ori_err_deg_mean | H10: Body/root orientation error (deg) | I10: lower | J10: 5.9036681 | K10: 5.661955 | L10: =K10-J10 -> -0.24171316 | M10: =IF(I10="higher",L10,-L10) -> 0.24171316
A11: corrected_vs_prg | B11: PRG | C11: G1 corrected | D11: box001_20231003_2_041_p1 | E11: box001 | F11: =TRUE() -> TRUE | G11: track_eef_pos_err_cm_mean | H11: Combined hand position error (cm) | I11: lower | J11: 13.689956 | K11: 11.740103 | L11: =K11-J11 -> -1.9498534 | M11: =IF(I11="higher",L11,-L11) -> 1.9498534
A12: corrected_vs_prg | B12: PRG | C12: G1 corrected | D12: box001_20231003_2_041_p1 | E12: box001 | F12: =TRUE() -> TRUE | G12: track_eef_ori_err_deg_mean | H12: Combined hand orientation error (deg) | I12: lower | J12: 22.982984 | K12: 17.084722 | L12: =K12-J12 -> -5.8982615 | M12: =IF(I12="higher",L12,-L12) -> 5.8982615
A13: corrected_vs_prg | B13: PRG | C13: G1 corrected | D13: box001_20231003_2_041_p1 | E13: box001 | F13: =TRUE() -> TRUE | G13: hand_object_physics_contact_3mm_in_mask_frac | H13: 3 mm contact fraction | I13: higher | J13: 0.81102362 | K13: 0.66929134 | L13: =K13-J13 -> -0.14173228 | M13: =IF(I13="higher",L13,-L13) -> -0.14173228
A14: corrected_vs_prg | B14: PRG | C14: G1 corrected | D14: box001_20231003_2_041_p1 | E14: box001 | F14: =TRUE() -> TRUE | G14: hand_object_physics_contact_in_mask_frac | H14: Raw contact fraction | I14: higher | J14: 0.8976378 | K14: 0.92125984 | L14: =K14-J14 -> 0.023622047 | M14: =IF(I14="higher",L14,-L14) -> 0.023622047
A15: corrected_vs_prg | B15: PRG | C15: G1 corrected | D15: box001_20231003_2_041_p1 | E15: box001 | F15: =TRUE() -> TRUE | G15: hand_object_release_false_contact_3mm_frac | H15: False release fraction | I15: lower | J15: 0.1 | K15: 0 | L15: =K15-J15 -> -0.1 | M15: =IF(I15="higher",L15,-L15) -> 0.1
A16: corrected_vs_prg | B16: PRG | C16: G1 corrected | D16: box001_20231003_2_041_p1 | E16: box001 | F16: =TRUE() -> TRUE | G16: hand_object_physics_penetration_3mm_frame_frac | H16: Hand penetration fraction | I16: lower | J16: 0.076433121 | K16: 0.20382166 | L16: =K16-J16 -> 0.12738854 | M16: =IF(I16="higher",L16,-L16) -> -0.12738854
... A452: corrected_vs_contaminated_g1 | B452: G1 contaminated | C452: G1 corrected | D452: box001_20231023_108_p1 | E452: box001 | F452: =TRUE() -> TRUE | G452: fall_flag | H452: Fall flag | I452: lower | J452: 0 | K452: 0 | L452: =K452-J452 -> 0 | M452: =IF(I452="higher",L452,-L452) -> 0
A453: corrected_vs_prg | B453: PRG | C453: G1 corrected | D453: box001_20231023_110_p1 | E453: box001 | F453: =FALSE() -> FALSE | G453: track_obj_z_abs_err_cm_mean | H453: Object z MAE (cm) | I453: lower | J453: 3.724824 | K453: 1.718997 | L453: =K453-J453 -> -2.005827 | M453: =IF(I453="higher",L453,-L453) -> 2.005827
A454: corrected_vs_prg | B454: PRG | C454: G1 corrected | D454: box001_20231023_110_p1 | E454: box001 | F454: =FALSE() -> FALSE | G454: track_obj_pos_err_cm_mean | H454: Object 3D position error (cm) | I454: lower | J454: 7.9584106 | K454: 5.1475154 | L454: =K454-J454 -> -2.8108952 | M454: =IF(I454="higher",L454,-L454) -> 2.8108952
A455: corrected_vs_prg | B455: PRG | C455: G1 corrected | D455: box001_20231023_110_p1 | E455: box001 | F455: =FALSE() -> FALSE | G455: track_obj_ori_err_deg_mean | H455: Object orientation error (deg) | I455: lower | J455: 5.4509958 | K455: 3.9939979 | L455: =K455-J455 -> -1.4569979 | M455: =IF(I455="higher",L455,-L455) -> 1.4569979
A456: corrected_vs_prg | B456: PRG | C456: G1 corrected | D456: box001_20231023_110_p1 | E456: box001 | F456: =FALSE() -> FALSE | G456: body_z_err_p95_m | H456: Body z error p95 (m) | I456: lower | J456: 0.45485022 | K456: 0.46834218 | L456: =K456-J456 -> 0.013491961 | M456: =IF(I456="higher",L456,-L456) -> -0.013491961
A457: corrected_vs_prg | B457: PRG | C457: G1 corrected | D457: box001_20231023_110_p1 | E457: box001 | F457: =FALSE() -> FALSE | G457: track_root_pos_err_cm_mean | H457: Body/root position error (cm) | I457: lower | J457: 563.14372 | K457: 535.78342 | L457: =K457-J457 -> -27.360297 | M457: =IF(I457="higher",L457,-L457) -> 27.360297
A458: corrected_vs_prg | B458: PRG | C458: G1 corrected | D458: box001_20231023_110_p1 | E458: box001 | F458: =FALSE() -> FALSE | G458: track_root_ori_err_deg_mean | H458: Body/root orientation error (deg) | I458: lower | J458: 124.53824 | K458: 127.46103 | L458: =K458-J458 -> 2.9227827 | M458: =IF(I458="higher",L458,-L458) -> -2.9227827
A459: corrected_vs_prg | B459: PRG | C459: G1 corrected | D459: box001_20231023_110_p1 | E459: box001 | F459: =FALSE() -> FALSE | G459: track_eef_pos_err_cm_mean | H459: Combined hand position error (cm) | I459: lower | J459: 579.23326 | K459: 553.00866 | L459: =K459-J459 -> -26.224597 | M459: =IF(I459="higher",L459,-L459) -> 26.224597
A460: corrected_vs_prg | B460: PRG | C460: G1 corrected | D460: box001_20231023_110_p1 | E460: box001 | F460: =FALSE() -> FALSE | G460: track_eef_ori_err_deg_mean | H460: Combined hand orientation error (deg) | I460: lower | J460: 126.19206 | K460: 127.02563 | L460: =K460-J460 -> 0.83357005 | M460: =IF(I460="higher",L460,-L460) -> -0.83357005
A461: corrected_vs_prg | B461: PRG | C461: G1 corrected | D461: box001_20231023_110_p1 | E461: box001 | F461: =FALSE() -> FALSE | G461: hand_object_physics_contact_3mm_in_mask_frac | H461: 3 mm contact fraction | I461: higher | J461: 0 | K461: 0 | L461: =K461-J461 -> 0 | M461: =IF(I461="higher",L461,-L461) -> 0
A462: corrected_vs_prg | B462: PRG | C462: G1 corrected | D462: box001_20231023_110_p1 | E462: box001 | F462: =FALSE() -> FALSE | G462: hand_object_physics_contact_in_mask_frac | H462: Raw contact fraction | I462: higher | J462: 0 | K462: 0 | L462: =K462-J462 -> 0 | M462: =IF(I462="higher",L462,-L462) -> 0
A463: corrected_vs_prg | B463: PRG | C463: G1 corrected | D463: box001_20231023_110_p1 | E463: box001 | F463: =FALSE() -> FALSE | G463: hand_object_release_false_contact_3mm_frac | H463: False release fraction | I463: lower | J463: 0 | K463: 0 | L463: =K463-J463 -> 0 | M463: =IF(I463="higher",L463,-L463) -> 0
A464: corrected_vs_prg | B464: PRG | C464: G1 corrected | D464: box001_20231023_110_p1 | E464: box001 | F464: =FALSE() -> FALSE | G464: hand_object_physics_penetration_3mm_frame_frac | H464: Hand penetration fraction | I464: lower | J464: 0 | K464: 0 | L464: =K464-J464 -> 0 | M464: =IF(I464="higher",L464,-L464) -> 0
... A480: corrected_vs_contaminated_g1 | B480: G1 contaminated | C480: G1 corrected | D480: box001_20231023_110_p1 | E480: box001 | F480: =FALSE() -> FALSE | G480: fall_flag | H480: Fall flag | I480: lower | J480: 1 | K480: 1 | L480: =K480-J480 -> 0 | M480: =IF(I480="higher",L480,-L480) -> 0
A481: corrected_vs_prg | B481: PRG | C481: G1 corrected | D481: box023_20231008_046_p2 | E481: box023 | F481: =TRUE() -> TRUE | G481: track_obj_z_abs_err_cm_mean | H481: Object z MAE (cm) | I481: lower | J481: 4.7984659 | K481: 5.5226018 | L481: =K481-J481 -> 0.72413592 | M481: =IF(I481="higher",L481,-L481) -> -0.72413592
A482: corrected_vs_prg | B482: PRG | C482: G1 corrected | D482: box023_20231008_046_p2 | E482: box023 | F482: =TRUE() -> TRUE | G482: track_obj_pos_err_cm_mean | H482: Object 3D position error (cm) | I482: lower | J482: 6.8416149 | K482: 7.2877091 | L482: =K482-J482 -> 0.44609416 | M482: =IF(I482="higher",L482,-L482) -> -0.44609416
A483: corrected_vs_prg | B483: PRG | C483: G1 corrected | D483: box023_20231008_046_p2 | E483: box023 | F483: =TRUE() -> TRUE | G483: track_obj_ori_err_deg_mean | H483: Object orientation error (deg) | I483: lower | J483: 4.5604681 | K483: 5.1392116 | L483: =K483-J483 -> 0.57874349 | M483: =IF(I483="higher",L483,-L483) -> -0.57874349
A484: corrected_vs_prg | B484: PRG | C484: G1 corrected | D484: box023_20231008_046_p2 | E484: box023 | F484: =TRUE() -> TRUE | G484: body_z_err_p95_m | H484: Body z error p95 (m) | I484: lower | J484: 0.16673359 | K484: 0.17692079 | L484: =K484-J484 -> 0.010187193 | M484: =IF(I484="higher",L484,-L484) -> -0.010187193
A485: corrected_vs_prg | B485: PRG | C485: G1 corrected | D485: box023_20231008_046_p2 | E485: box023 | F485: =TRUE() -> TRUE | G485: track_root_pos_err_cm_mean | H485: Body/root position error (cm) | I485: lower | J485: 12.468615 | K485: 13.923487 | L485: =K485-J485 -> 1.4548723 | M485: =IF(I485="higher",L485,-L485) -> -1.4548723
A486: corrected_vs_prg | B486: PRG | C486: G1 corrected | D486: box023_20231008_046_p2 | E486: box023 | F486: =TRUE() -> TRUE | G486: track_root_ori_err_deg_mean | H486: Body/root orientation error (deg) | I486: lower | J486: 17.018601 | K486: 14.376769 | L486: =K486-J486 -> -2.6418318 | M486: =IF(I486="higher",L486,-L486) -> 2.6418318
A487: corrected_vs_prg | B487: PRG | C487: G1 corrected | D487: box023_20231008_046_p2 | E487: box023 | F487: =TRUE() -> TRUE | G487: track_eef_pos_err_cm_mean | H487: Combined hand position error (cm) | I487: lower | J487: 11.862208 | K487: 13.523941 | L487: =K487-J487 -> 1.6617334 | M487: =IF(I487="higher",L487,-L487) -> -1.6617334
A488: corrected_vs_prg | B488: PRG | C488: G1 corrected | D488: box023_20231008_046_p2 | E488: box023 | F488: =TRUE() -> TRUE | G488: track_eef_ori_err_deg_mean | H488: Combined hand orientation error (deg) | I488: lower | J488: 23.668514 | K488: 22.916448 | L488: =K488-J488 -> -0.75206637 | M488: =IF(I488="higher",L488,-L488) -> 0.75206637
A489: corrected_vs_prg | B489: PRG | C489: G1 corrected | D489: box023_20231008_046_p2 | E489: box023 | F489: =TRUE() -> TRUE | G489: hand_object_physics_contact_3mm_in_mask_frac | H489: 3 mm contact fraction | I489: higher | J489: 0.44186047 | K489: 0.48837209 | L489: =K489-J489 -> 0.046511628 | M489: =IF(I489="higher",L489,-L489) -> 0.046511628
A490: corrected_vs_prg | B490: PRG | C490: G1 corrected | D490: box023_20231008_046_p2 | E490: box023 | F490: =TRUE() -> TRUE | G490: hand_object_physics_contact_in_mask_frac | H490: Raw contact fraction | I490: higher | J490: 0.53488372 | K490: 0.65116279 | L490: =K490-J490 -> 0.11627907 | M490: =IF(I490="higher",L490,-L490) -> 0.11627907
A491: corrected_vs_prg | B491: PRG | C491: G1 corrected | D491: box023_20231008_046_p2 | E491: box023 | F491: =TRUE() -> TRUE | G491: hand_object_release_false_contact_3mm_frac | H491: False release fraction | I491: lower | J491: 0.052631579 | K491: 0.052631579 | L491: =K491-J491 -> 0 | M491: =IF(I491="higher",L491,-L491) -> 0
...

Sheet By Object
A1: By-object formula summary
A2: Means, deltas, improvements and counts are Excel formulas over Paired Comparison; bootstrap CI uses fixed-seed evidence.
A4: Subset | B4: Comparison | C4: Metric key | D4: Metric | E4: Direction | F4: N | G4: Baseline mean | H4: Candidate mean | I4: Raw Delta | J4: Improvement | K4: Median improvement | L4: Bootstrap 95% CI low | M4: Bootstrap 95% CI high | N4: Improved cases | O4: Worsened cases
A5: ALL_AFFECTED_29 | B5: corrected_vs_prg | C5: track_obj_z_abs_err_cm_mean | D5: Object z MAE (cm) | E5: lower | F5: =COUNTIFS('Paired Comparison'!$A:$A,$B5,'Paired Comparison'!$G:$G,$C5) -> 29 | G5: =AVERAGEIFS('Paired Comparison'!$J:$J,'Paired Comparison'!$A:$A,$B5,'Paired Comparison'!$G:$G,$C5) -> 4.9536065 | H5: =AVERAGEIFS('Paired Comparison'!$K:$K,'Paired Comparison'!$A:$A,$B5,'Paired Comparison'!$G:$G,$C5) -> 3.6012283 | I5: =H5-G5 -> -1.3523782 | J5: =IF(E5="higher",I5,-I5) -> 1.3523782 | K5: 1.506592 | L5: 1.0002586 | M5: 1.7060408 | N5: =COUNTIFS('Paired Comparison'!$A:$A,$B5,'Paired Comparison'!$G:$G,$C5,'Paired Comparison'!$M:$M,">0") -> 27 | O5: =COUNTIFS('Paired Comparison'!$A:$A,$B5,'Paired Comparison'!$G:$G,$C5,'Paired Comparison'!$M:$M,"<0") -> 2
A6: ALL_AFFECTED_29 | B6: corrected_vs_prg | C6: track_obj_pos_err_cm_mean | D6: Object 3D position error (cm) | E6: lower | F6: =COUNTIFS('Paired Comparison'!$A:$A,$B6,'Paired Comparison'!$G:$G,$C6) -> 29 | G6: =AVERAGEIFS('Paired Comparison'!$J:$J,'Paired Comparison'!$A:$A,$B6,'Paired Comparison'!$G:$G,$C6) -> 11.511283 | H6: =AVERAGEIFS('Paired Comparison'!$K:$K,'Paired Comparison'!$A:$A,$B6,'Paired Comparison'!$G:$G,$C6) -> 9.9528347 | I6: =H6-G6 -> -1.5584488 | J6: =IF(E6="higher",I6,-I6) -> 1.5584488 | K6: 1.1877137 | L6: 0.89816745 | M6: 2.2536699 | N6: =COUNTIFS('Paired Comparison'!$A:$A,$B6,'Paired Comparison'!$G:$G,$C6,'Paired Comparison'!$M:$M,">0") -> 22 | O6: =COUNTIFS('Paired Comparison'!$A:$A,$B6,'Paired Comparison'!$G:$G,$C6,'Paired Comparison'!$M:$M,"<0") -> 7
A7: ALL_AFFECTED_29 | B7: corrected_vs_prg | C7: track_obj_ori_err_deg_mean | D7: Object orientation error (deg) | E7: lower | F7: =COUNTIFS('Paired Comparison'!$A:$A,$B7,'Paired Comparison'!$G:$G,$C7) -> 29 | G7: =AVERAGEIFS('Paired Comparison'!$J:$J,'Paired Comparison'!$A:$A,$B7,'Paired Comparison'!$G:$G,$C7) -> 5.832045 | H7: =AVERAGEIFS('Paired Comparison'!$K:$K,'Paired Comparison'!$A:$A,$B7,'Paired Comparison'!$G:$G,$C7) -> 5.111908 | I7: =H7-G7 -> -0.720137 | J7: =IF(E7="higher",I7,-I7) -> 0.720137 | K7: 0.60191639 | L7: 0.20160464 | M7: 1.2476823 | N7: =COUNTIFS('Paired Comparison'!$A:$A,$B7,'Paired Comparison'!$G:$G,$C7,'Paired Comparison'!$M:$M,">0") -> 19 | O7: =COUNTIFS('Paired Comparison'!$A:$A,$B7,'Paired Comparison'!$G:$G,$C7,'Paired Comparison'!$M:$M,"<0") -> 10
A8: ALL_AFFECTED_29 | B8: corrected_vs_prg | C8: body_z_err_p95_m | D8: Body z error p95 (m) | E8: lower | F8: =COUNTIFS('Paired Comparison'!$A:$A,$B8,'Paired Comparison'!$G:$G,$C8) -> 29 | G8: =AVERAGEIFS('Paired Comparison'!$J:$J,'Paired Comparison'!$A:$A,$B8,'Paired Comparison'!$G:$G,$C8) -> 0.11383933 | H8: =AVERAGEIFS('Paired Comparison'!$K:$K,'Paired Comparison'!$A:$A,$B8,'Paired Comparison'!$G:$G,$C8) -> 0.10090299 | I8: =H8-G8 -> -0.012936337 | J8: =IF(E8="higher",I8,-I8) -> 0.012936337 | K8: 0.011635663 | L8: 0.0074106101 | M8: 0.01843626 | N8: =COUNTIFS('Paired Comparison'!$A:$A,$B8,'Paired Comparison'!$G:$G,$C8,'Paired Comparison'!$M:$M,">0") -> 22 | O8: =COUNTIFS('Paired Comparison'!$A:$A,$B8,'Paired Comparison'!$G:$G,$C8,'Paired Comparison'!$M:$M,"<0") -> 7
A9: ALL_AFFECTED_29 | B9: corrected_vs_prg | C9: track_root_pos_err_cm_mean | D9: Body/root position error (cm) | E9: lower | F9: =COUNTIFS('Paired Comparison'!$A:$A,$B9,'Paired Comparison'!$G:$G,$C9) -> 29 | G9: =AVERAGEIFS('Paired Comparison'!$J:$J,'Paired Comparison'!$A:$A,$B9,'Paired Comparison'!$G:$G,$C9) -> 35.577268 | H9: =AVERAGEIFS('Paired Comparison'!$K:$K,'Paired Comparison'!$A:$A,$B9,'Paired Comparison'!$G:$G,$C9) -> 34.464643 | I9: =H9-G9 -> -1.112625 | J9: =IF(E9="higher",I9,-I9) -> 1.112625 | K9: 0.4011549 | L9: -0.8610572 | M9: 3.6046781 | N9: =COUNTIFS('Paired Comparison'!$A:$A,$B9,'Paired Comparison'!$G:$G,$C9,'Paired Comparison'!$M:$M,">0") -> 16 | O9: =COUNTIFS('Paired Comparison'!$A:$A,$B9,'Paired Comparison'!$G:$G,$C9,'Paired Comparison'!$M:$M,"<0") -> 13
A10: ALL_AFFECTED_29 | B10: corrected_vs_prg | C10: track_root_ori_err_deg_mean | D10: Body/root orientation error (deg) | E10: lower | F10: =COUNTIFS('Paired Comparison'!$A:$A,$B10,'Paired Comparison'!$G:$G,$C10) -> 29 | G10: =AVERAGEIFS('Paired Comparison'!$J:$J,'Paired Comparison'!$A:$A,$B10,'Paired Comparison'!$G:$G,$C10) -> 15.246188 | H10: =AVERAGEIFS('Paired Comparison'!$K:$K,'Paired Comparison'!$A:$A,$B10,'Paired Comparison'!$G:$G,$C10) -> 13.730444 | I10: =H10-G10 -> -1.5157437 | J10: =IF(E10="higher",I10,-I10) -> 1.5157437 | K10: 0.72942454 | L10: 0.44574007 | M10: 2.6837839 | N10: =COUNTIFS('Paired Comparison'!$A:$A,$B10,'Paired Comparison'!$G:$G,$C10,'Paired Comparison'!$M:$M,">0") -> 20 | O10: =COUNTIFS('Paired Comparison'!$A:$A,$B10,'Paired Comparison'!$G:$G,$C10,'Paired Comparison'!$M:$M,"<0") -> 9
A11: ALL_AFFECTED_29 | B11: corrected_vs_prg | C11: track_eef_pos_err_cm_mean | D11: Combined hand position error (cm) | E11: lower | F11: =COUNTIFS('Paired Comparison'!$A:$A,$B11,'Paired Comparison'!$G:$G,$C11) -> 29 | G11: =AVERAGEIFS('Paired Comparison'!$J:$J,'Paired Comparison'!$A:$A,$B11,'Paired Comparison'!$G:$G,$C11) -> 35.595735 | H11: =AVERAGEIFS('Paired Comparison'!$K:$K,'Paired Comparison'!$A:$A,$B11,'Paired Comparison'!$G:$G,$C11) -> 34.149499 | I11: =H11-G11 -> -1.4462358 | J11: =IF(E11="higher",I11,-I11) -> 1.4462358 | K11: 0.018843797 | L11: -0.31948706 | M11: 3.6946327 | N11: =COUNTIFS('Paired Comparison'!$A:$A,$B11,'Paired Comparison'!$G:$G,$C11,'Paired Comparison'!$M:$M,">0") -> 15 | O11: =COUNTIFS('Paired Comparison'!$A:$A,$B11,'Paired Comparison'!$G:$G,$C11,'Paired Comparison'!$M:$M,"<0") -> 14
A12: ALL_AFFECTED_29 | B12: corrected_vs_prg | C12: track_eef_ori_err_deg_mean | D12: Combined hand orientation error (deg) | E12: lower | F12: =COUNTIFS('Paired Comparison'!$A:$A,$B12,'Paired Comparison'!$G:$G,$C12) -> 29 | G12: =AVERAGEIFS('Paired Comparison'!$J:$J,'Paired Comparison'!$A:$A,$B12,'Paired Comparison'!$G:$G,$C12) -> 23.162256 | H12: =AVERAGEIFS('Paired Comparison'!$K:$K,'Paired Comparison'!$A:$A,$B12,'Paired Comparison'!$G:$G,$C12) -> 22.100898 | I12: =H12-G12 -> -1.0613583 | J12: =IF(E12="higher",I12,-I12) -> 1.0613583 | K12: 0.67420125 | L12: -0.035372947 | M12: 2.1463321 | N12: =COUNTIFS('Paired Comparison'!$A:$A,$B12,'Paired Comparison'!$G:$G,$C12,'Paired Comparison'!$M:$M,">0") -> 20 | O12: =COUNTIFS('Paired Comparison'!$A:$A,$B12,'Paired Comparison'!$G:$G,$C12,'Paired Comparison'!$M:$M,"<0") -> 9
A13: ALL_AFFECTED_29 | B13: corrected_vs_prg | C13: hand_object_physics_contact_3mm_in_mask_frac | D13: 3 mm contact fraction | E13: higher | F13: =COUNTIFS('Paired Comparison'!$A:$A,$B13,'Paired Comparison'!$G:$G,$C13) -> 29 | G13: =AVERAGEIFS('Paired Comparison'!$J:$J,'Paired Comparison'!$A:$A,$B13,'Paired Comparison'!$G:$G,$C13) -> 0.49535384 | H13: =AVERAGEIFS('Paired Comparison'!$K:$K,'Paired Comparison'!$A:$A,$B13,'Paired Comparison'!$G:$G,$C13) -> 0.53264875 | I13: =H13-G13 -> 0.037294911 | J13: =IF(E13="higher",I13,-I13) -> 0.037294911 | K13: 0.020408163 | L13: -0.0057225405 | M13: 0.08020046 | N13: =COUNTIFS('Paired Comparison'!$A:$A,$B13,'Paired Comparison'!$G:$G,$C13,'Paired Comparison'!$M:$M,">0") -> 18 | O13: =COUNTIFS('Paired Comparison'!$A:$A,$B13,'Paired Comparison'!$G:$G,$C13,'Paired Comparison'!$M:$M,"<0") -> 8
A14: ALL_AFFECTED_29 | B14: corrected_vs_prg | C14: hand_object_physics_contact_in_mask_frac | D14: Raw contact fraction | E14: higher | F14: =COUNTIFS('Paired Comparison'!$A:$A,$B14,'Paired Comparison'!$G:$G,$C14) -> 29 | G14: =AVERAGEIFS('Paired Comparison'!$J:$J,'Paired Comparison'!$A:$A,$B14,'Paired Comparison'!$G:$G,$C14) -> 0.77944999 | H14: =AVERAGEIFS('Paired Comparison'!$K:$K,'Paired Comparison'!$A:$A,$B14,'Paired Comparison'!$G:$G,$C14) -> 0.77325901 | I14: =H14-G14 -> -0.0061909752 | J14: =IF(E14="higher",I14,-I14) -> -0.0061909752 | K14: 0 | L14: -0.037962046 | M14: 0.022824723 | N14: =COUNTIFS('Paired Comparison'!$A:$A,$B14,'Paired Comparison'!$G:$G,$C14,'Paired Comparison'!$M:$M,">0") -> 10 | O14: =COUNTIFS('Paired Comparison'!$A:$A,$B14,'Paired Comparison'!$G:$G,$C14,'Paired Comparison'!$M:$M,"<0") -> 12
A15: ALL_AFFECTED_29 | B15: corrected_vs_prg | C15: hand_object_release_false_contact_3mm_frac | D15: False release fraction | E15: lower | F15: =COUNTIFS('Paired Comparison'!$A:$A,$B15,'Paired Comparison'!$G:$G,$C15) -> 29 | G15: =AVERAGEIFS('Paired Comparison'!$J:$J,'Paired Comparison'!$A:$A,$B15,'Paired Comparison'!$G:$G,$C15) -> 0.098770535 | H15: =AVERAGEIFS('Paired Comparison'!$K:$K,'Paired Comparison'!$A:$A,$B15,'Paired Comparison'!$G:$G,$C15) -> 0.096473121 | I15: =H15-G15 -> -0.0022974141 | J15: =IF(E15="higher",I15,-I15) -> 0.0022974141 | K15: 0 | L15: -0.042400231 | M15: 0.036908856 | N15: =COUNTIFS('Paired Comparison'!$A:$A,$B15,'Paired Comparison'!$G:$G,$C15,'Paired Comparison'!$M:$M,">0") -> 11 | O15: =COUNTIFS('Paired Comparison'!$A:$A,$B15,'Paired Comparison'!$G:$G,$C15,'Paired Comparison'!$M:$M,"<0") -> 6
A16: ALL_AFFECTED_29 | B16: corrected_vs_prg | C16: hand_object_physics_penetration_3mm_frame_frac | D16: Hand penetration fraction | E16: lower | F16: =COUNTIFS('Paired Comparison'!$A:$A,$B16,'Paired Comparison'!$G:$G,$C16) -> 29 | G16: =AVERAGEIFS('Paired Comparison'!$J:$J,'Paired Comparison'!$A:$A,$B16,'Paired Comparison'!$G:$G,$C16) -> 0.19188379 | H16: =AVERAGEIFS('Paired Comparison'!$K:$K,'Paired Comparison'!$A:$A,$B16,'Paired Comparison'!$G:$G,$C16) -> 0.16622147 | I16: =H16-G16 -> -0.02566232 | J16: =IF(E16="higher",I16,-I16) -> 0.02566232 | K16: 0.015789474 | L16: -0.011555207 | M16: 0.062662153 | N16: =COUNTIFS('Paired Comparison'!$A:$A,$B16,'Paired Comparison'!$G:$G,$C16,'Paired Comparison'!$M:$M,">0") -> 17 | O16: =COUNTIFS('Paired Comparison'!$A:$A,$B16,'Paired Comparison'!$G:$G,$C16,'Paired Comparison'!$M:$M,"<0") -> 8
... A32: ALL_AFFECTED_29 | B32: corrected_vs_contaminated_g1 | C32: fall_flag | D32: Fall flag | E32: lower | F32: =COUNTIFS('Paired Comparison'!$A:$A,$B32,'Paired Comparison'!$G:$G,$C32) -> 29 | G32: =AVERAGEIFS('Paired Comparison'!$J:$J,'Paired Comparison'!$A:$A,$B32,'Paired Comparison'!$G:$G,$C32) -> 0.034482759 | H32: =AVERAGEIFS('Paired Comparison'!$K:$K,'Paired Comparison'!$A:$A,$B32,'Paired Comparison'!$G:$G,$C32) -> 0.034482759 | I32: =H32-G32 -> 0 | J32: =IF(E32="higher",I32,-I32) -> 0 | K32: 0 | L32: 0 | M32: 0 | N32: =COUNTIFS('Paired Comparison'!$A:$A,$B32,'Paired Comparison'!$G:$G,$C32,'Paired Comparison'!$M:$M,">0") -> 0 | O32: =COUNTIFS('Paired Comparison'!$A:$A,$B32,'Paired Comparison'!$G:$G,$C32,'Paired Comparison'!$M:$M,"<0") -> 0
A33: BOX001_ALL_AFFECTED_21 | B33: corrected_vs_prg | C33: track_obj_z_abs_err_cm_mean | D33: Object z MAE (cm) | E33: lower | F33: =COUNTIFS('Paired Comparison'!$A:$A,$B33,'Paired Comparison'!$G:$G,$C33,'Paired Comparison'!$E:$E,"box001") -> 21 | G33: =AVERAGEIFS('Paired Comparison'!$J:$J,'Paired Comparison'!$A:$A,$B33,'Paired Comparison'!$G:$G,$C33,'Paired Comparison'!$E:$E,"box001") -> 4.7403406 | H33: =AVERAGEIFS('Paired Comparison'!$K:$K,'Paired Comparison'!$A:$A,$B33,'Paired Comparison'!$G:$G,$C33,'Paired Comparison'!$E:$E,"box001") -> 3.082 | I33: =H33-G33 -> -1.6583406 | J33: =IF(E33="higher",I33,-I33) -> 1.6583406 | K33: 1.6987456 | L33: 1.3030007 | M33: 2.0188504 | N33: =COUNTIFS('Paired Comparison'!$A:$A,$B33,'Paired Comparison'!$G:$G,$C33,'Paired Comparison'!$E:$E,"box001",'Paired Comparison'!$M:$M,">0") -> 21 | O33: =COUNTIFS('Paired Comparison'!$A:$A,$B33,'Paired Comparison'!$G:$G,$C33,'Paired Comparison'!$E:$E,"box001",'Paired Comparison'!$M:$M,"<0") -> 0
A34: BOX001_ALL_AFFECTED_21 | B34: corrected_vs_prg | C34: track_obj_pos_err_cm_mean | D34: Object 3D position error (cm) | E34: lower | F34: =COUNTIFS('Paired Comparison'!$A:$A,$B34,'Paired Comparison'!$G:$G,$C34,'Paired Comparison'!$E:$E,"box001") -> 21 | G34: =AVERAGEIFS('Paired Comparison'!$J:$J,'Paired Comparison'!$A:$A,$B34,'Paired Comparison'!$G:$G,$C34,'Paired Comparison'!$E:$E,"box001") -> 10.878354 | H34: =AVERAGEIFS('Paired Comparison'!$K:$K,'Paired Comparison'!$A:$A,$B34,'Paired Comparison'!$G:$G,$C34,'Paired Comparison'!$E:$E,"box001") -> 9.2673482 | I34: =H34-G34 -> -1.6110061 | J34: =IF(E34="higher",I34,-I34) -> 1.6110061 | K34: 1.3580938 | L34: 0.85875858 | M34: 2.4314382 | N34: =COUNTIFS('Paired Comparison'!$A:$A,$B34,'Paired Comparison'!$G:$G,$C34,'Paired Comparison'!$E:$E,"box001",'Paired Comparison'!$M:$M,">0") -> 16 | O34: =COUNTIFS('Paired Comparison'!$A:$A,$B34,'Paired Comparison'!$G:$G,$C34,'Paired Comparison'!$E:$E,"box001",'Paired Comparison'!$M:$M,"<0") -> 5
A35: BOX001_ALL_AFFECTED_21 | B35: corrected_vs_prg | C35: track_obj_ori_err_deg_mean | D35: Object orientation error (deg) | E35: lower | F35: =COUNTIFS('Paired Comparison'!$A:$A,$B35,'Paired Comparison'!$G:$G,$C35,'Paired Comparison'!$E:$E,"box001") -> 21 | G35: =AVERAGEIFS('Paired Comparison'!$J:$J,'Paired Comparison'!$A:$A,$B35,'Paired Comparison'!$G:$G,$C35,'Paired Comparison'!$E:$E,"box001") -> 6.0458691 | H35: =AVERAGEIFS('Paired Comparison'!$K:$K,'Paired Comparison'!$A:$A,$B35,'Paired Comparison'!$G:$G,$C35,'Paired Comparison'!$E:$E,"box001") -> 5.1985126 | I35: =H35-G35 -> -0.84735644 | J35: =IF(E35="higher",I35,-I35) -> 0.84735644 | K35: 0.67947254 | L35: 0.28130923 | M35: 1.4079497 | N35: =COUNTIFS('Paired Comparison'!$A:$A,$B35,'Paired Comparison'!$G:$G,$C35,'Paired Comparison'!$E:$E,"box001",'Paired Comparison'!$M:$M,">0") -> 16 | O35: =COUNTIFS('Paired Comparison'!$A:$A,$B35,'Paired Comparison'!$G:$G,$C35,'Paired Comparison'!$E:$E,"box001",'Paired Comparison'!$M:$M,"<0") -> 5
A36: BOX001_ALL_AFFECTED_21 | B36: corrected_vs_prg | C36: body_z_err_p95_m | D36: Body z error p95 (m) | E36: lower | F36: =COUNTIFS('Paired Comparison'!$A:$A,$B36,'Paired Comparison'!$G:$G,$C36,'Paired Comparison'!$E:$E,"box001") -> 21 | G36: =AVERAGEIFS('Paired Comparison'!$J:$J,'Paired Comparison'!$A:$A,$B36,'Paired Comparison'!$G:$G,$C36,'Paired Comparison'!$E:$E,"box001") -> 0.10086714 | H36: =AVERAGEIFS('Paired Comparison'!$K:$K,'Paired Comparison'!$A:$A,$B36,'Paired Comparison'!$G:$G,$C36,'Paired Comparison'!$E:$E,"box001") -> 0.087765081 | I36: =H36-G36 -> -0.013102055 | J36: =IF(E36="higher",I36,-I36) -> 0.013102055 | K36: 0.011635663 | L36: 0.0073274006 | M36: 0.018948461 | N36: =COUNTIFS('Paired Comparison'!$A:$A,$B36,'Paired Comparison'!$G:$G,$C36,'Paired Comparison'!$E:$E,"box001",'Paired Comparison'!$M:$M,">0") -> 17 | O36: =COUNTIFS('Paired Comparison'!$A:$A,$B36,'Paired Comparison'!$G:$G,$C36,'Paired Comparison'!$E:$E,"box001",'Paired Comparison'!$M:$M,"<0") -> 4
A37: BOX001_ALL_AFFECTED_21 | B37: corrected_vs_prg | C37: track_root_pos_err_cm_mean | D37: Body/root position error (cm) | E37: lower | F37: =COUNTIFS('Paired Comparison'!$A:$A,$B37,'Paired Comparison'!$G:$G,$C37,'Paired Comparison'!$E:$E,"box001") -> 21 | G37: =AVERAGEIFS('Paired Comparison'!$J:$J,'Paired Comparison'!$A:$A,$B37,'Paired Comparison'!$G:$G,$C37,'Paired Comparison'!$E:$E,"box001") -> 42.261127 | H37: =AVERAGEIFS('Paired Comparison'!$K:$K,'Paired Comparison'!$A:$A,$B37,'Paired Comparison'!$G:$G,$C37,'Paired Comparison'!$E:$E,"box001") -> 41.215019 | I37: =H37-G37 -> -1.0461082 | J37: =IF(E37="higher",I37,-I37) -> 1.0461082 | K37: -0.93172591 | L37: -1.4346539 | M37: 4.4188763 | N37: =COUNTIFS('Paired Comparison'!$A:$A,$B37,'Paired Comparison'!$G:$G,$C37,'Paired Comparison'!$E:$E,"box001",'Paired Comparison'!$M:$M,">0") -> 10 | O37: =COUNTIFS('Paired Comparison'!$A:$A,$B37,'Paired Comparison'!$G:$G,$C37,'Paired Comparison'!$E:$E,"box001",'Paired Comparison'!$M:$M,"<0") -> 11
A38: BOX001_ALL_AFFECTED_21 | B38: corrected_vs_prg | C38: track_root_ori_err_deg_mean | D38: Body/root orientation error (deg) | E38: lower | F38: =COUNTIFS('Paired Comparison'!$A:$A,$B38,'Paired Comparison'!$G:$G,$C38,'Paired Comparison'!$E:$E,"box001") -> 21 | G38: =AVERAGEIFS('Paired Comparison'!$J:$J,'Paired Comparison'!$A:$A,$B38,'Paired Comparison'!$G:$G,$C38,'Paired Comparison'!$E:$E,"box001") -> 15.360306 | H38: =AVERAGEIFS('Paired Comparison'!$K:$K,'Paired Comparison'!$A:$A,$B38,'Paired Comparison'!$G:$G,$C38,'Paired Comparison'!$E:$E,"box001") -> 14.410529 | I38: =H38-G38 -> -0.94977718 | J38: =IF(E38="higher",I38,-I38) -> 0.94977718 | K38: 0.29105342 | L38: -0.26154168 | M38: 2.354742 | N38: =COUNTIFS('Paired Comparison'!$A:$A,$B38,'Paired Comparison'!$G:$G,$C38,'Paired Comparison'!$E:$E,"box001",'Paired Comparison'!$M:$M,">0") -> 13 | O38: =COUNTIFS('Paired Comparison'!$A:$A,$B38,'Paired Comparison'!$G:$G,$C38,'Paired Comparison'!$E:$E,"box001",'Paired Comparison'!$M:$M,"<0") -> 8
A39: BOX001_ALL_AFFECTED_21 | B39: corrected_vs_prg | C39: track_eef_pos_err_cm_mean | D39: Combined hand position error (cm) | E39: lower | F39: =COUNTIFS('Paired Comparison'!$A:$A,$B39,'Paired Comparison'!$G:$G,$C39,'Paired Comparison'!$E:$E,"box001") -> 21 | G39: =AVERAGEIFS('Paired Comparison'!$J:$J,'Paired Comparison'!$A:$A,$B39,'Paired Comparison'!$G:$G,$C39,'Paired Comparison'!$E:$E,"box001") -> 42.824592 | H39: =AVERAGEIFS('Paired Comparison'!$K:$K,'Paired Comparison'!$A:$A,$B39,'Paired Comparison'!$G:$G,$C39,'Paired Comparison'!$E:$E,"box001") -> 41.319281 | I39: =H39-G39 -> -1.5053108 | J39: =IF(E39="higher",I39,-I39) -> 1.5053108 | K39: -0.78986664 | L39: -0.80118182 | M39: 4.5566058 | N39: =COUNTIFS('Paired Comparison'!$A:$A,$B39,'Paired Comparison'!$G:$G,$C39,'Paired Comparison'!$E:$E,"box001",'Paired Comparison'!$M:$M,">0") -> 10 | O39: =COUNTIFS('Paired Comparison'!$A:$A,$B39,'Paired Comparison'!$G:$G,$C39,'Paired Comparison'!$E:$E,"box001",'Paired Comparison'!$M:$M,"<0") -> 11
A40: BOX001_ALL_AFFECTED_21 | B40: corrected_vs_prg | C40: track_eef_ori_err_deg_mean | D40: Combined hand orientation error (deg) | E40: lower | F40: =COUNTIFS('Paired Comparison'!$A:$A,$B40,'Paired Comparison'!$G:$G,$C40,'Paired Comparison'!$E:$E,"box001") -> 21 | G40: =AVERAGEIFS('Paired Comparison'!$J:$J,'Paired Comparison'!$A:$A,$B40,'Paired Comparison'!$G:$G,$C40,'Paired Comparison'!$E:$E,"box001") -> 23.682021 | H40: =AVERAGEIFS('Paired Comparison'!$K:$K,'Paired Comparison'!$A:$A,$B40,'Paired Comparison'!$G:$G,$C40,'Paired Comparison'!$E:$E,"box001") -> 23.06253 | I40: =H40-G40 -> -0.61949044 | J40: =IF(E40="higher",I40,-I40) -> 0.61949044 | K40: 0.097142442 | L40: -0.58270709 | M40: 1.8938645 | N40: =COUNTIFS('Paired Comparison'!$A:$A,$B40,'Paired Comparison'!$G:$G,$C40,'Paired Comparison'!$E:$E,"box001",'Paired Comparison'!$M:$M,">0") -> 13 | O40: =COUNTIFS('Paired Comparison'!$A:$A,$B40,'Paired Comparison'!$G:$G,$C40,'Paired Comparison'!$E:$E,"box001",'Paired Comparison'!$M:$M,"<0") -> 8
A41: BOX001_ALL_AFFECTED_21 | B41: corrected_vs_prg | C41: hand_object_physics_contact_3mm_in_mask_frac | D41: 3 mm contact fraction | E41: higher | F41: =COUNTIFS('Paired Comparison'!$A:$A,$B41,'Paired Comparison'!$G:$G,$C41,'Paired Comparison'!$E:$E,"box001") -> 21 | G41: =AVERAGEIFS('Paired Comparison'!$J:$J,'Paired Comparison'!$A:$A,$B41,'Paired Comparison'!$G:$G,$C41,'Paired Comparison'!$E:$E,"box001") -> 0.4906867 | H41: =AVERAGEIFS('Paired Comparison'!$K:$K,'Paired Comparison'!$A:$A,$B41,'Paired Comparison'!$G:$G,$C41,'Paired Comparison'!$E:$E,"box001") -> 0.54467014 | I41: =H41-G41 -> 0.053983437 | J41: =IF(E41="higher",I41,-I41) -> 0.053983437 | K41: 0.054347826 | L41: 0.0085439218 | M41: 0.098921618 | N41: =COUNTIFS('Paired Comparison'!$A:$A,$B41,'Paired Comparison'!$G:$G,$C41,'Paired Comparison'!$E:$E,"box001",'Paired Comparison'!$M:$M,">0") -> 15 | O41: =COUNTIFS('Paired Comparison'!$A:$A,$B41,'Paired Comparison'!$G:$G,$C41,'Paired Comparison'!$E:$E,"box001",'Paired Comparison'!$M:$M,"<0") -> 4
A42: BOX001_ALL_AFFECTED_21 | B42: corrected_vs_prg | C42: hand_object_physics_contact_in_mask_frac | D42: Raw contact fraction | E42: higher | F42: =COUNTIFS('Paired Comparison'!$A:$A,$B42,'Paired Comparison'!$G:$G,$C42,'Paired Comparison'!$E:$E,"box001") -> 21 | G42: =AVERAGEIFS('Paired Comparison'!$J:$J,'Paired Comparison'!$A:$A,$B42,'Paired Comparison'!$G:$G,$C42,'Paired Comparison'!$E:$E,"box001") -> 0.79987702 | H42: =AVERAGEIFS('Paired Comparison'!$K:$K,'Paired Comparison'!$A:$A,$B42,'Paired Comparison'!$G:$G,$C42,'Paired Comparison'!$E:$E,"box001") -> 0.78660751 | I42: =H42-G42 -> -0.013269504 | J42: =IF(E42="higher",I42,-I42) -> -0.013269504 | K42: 0 | L42: -0.053229696 | M42: 0.01872913 | N42: =COUNTIFS('Paired Comparison'!$A:$A,$B42,'Paired Comparison'!$G:$G,$C42,'Paired Comparison'!$E:$E,"box001",'Paired Comparison'!$M:$M,">0") -> 7 | O42: =COUNTIFS('Paired Comparison'!$A:$A,$B42,'Paired Comparison'!$G:$G,$C42,'Paired Comparison'!$E:$E,"box001",'Paired Comparison'!$M:$M,"<0") -> 8
A43: BOX001_ALL_AFFECTED_21 | B43: corrected_vs_prg | C43: hand_object_release_false_contact_3mm_frac | D43: False release fraction | E43: lower | F43: =COUNTIFS('Paired Comparison'!$A:$A,$B43,'Paired Comparison'!$G:$G,$C43,'Paired Comparison'!$E:$E,"box001") -> 21 | G43: =AVERAGEIFS('Paired Comparison'!$J:$J,'Paired Comparison'!$A:$A,$B43,'Paired Comparison'!$G:$G,$C43,'Paired Comparison'!$E:$E,"box001") -> 0.12594437 | H43: =AVERAGEIFS('Paired Comparison'!$K:$K,'Paired Comparison'!$A:$A,$B43,'Paired Comparison'!$G:$G,$C43,'Paired Comparison'!$E:$E,"box001") -> 0.12600109 | I43: =H43-G43 -> 5.6718271e-05 | J43: =IF(E43="higher",I43,-I43) -> -5.6718271e-05 | K43: 0 | L43: -0.061619813 | M43: 0.047388971 | N43: =COUNTIFS('Paired Comparison'!$A:$A,$B43,'Paired Comparison'!$G:$G,$C43,'Paired Comparison'!$E:$E,"box001",'Paired Comparison'!$M:$M,">0") -> 9 | O43: =COUNTIFS('Paired Comparison'!$A:$A,$B43,'Paired Comparison'!$G:$G,$C43,'Paired Comparison'!$E:$E,"box001",'Paired Comparison'!$M:$M,"<0") -> 6
A44: BOX001_ALL_AFFECTED_21 | B44: corrected_vs_prg | C44: hand_object_physics_penetration_3mm_frame_frac | D44: Hand penetration fraction | E44: lower | F44: =COUNTIFS('Paired Comparison'!$A:$A,$B44,'Paired Comparison'!$G:$G,$C44,'Paired Comparison'!$E:$E,"box001") -> 21 | G44: =AVERAGEIFS('Paired Comparison'!$J:$J,'Paired Comparison'!$A:$A,$B44,'Paired Comparison'!$G:$G,$C44,'Paired Comparison'!$E:$E,"box001") -> 0.21462744 | H44: =AVERAGEIFS('Paired Comparison'!$K:$K,'Paired Comparison'!$A:$A,$B44,'Paired Comparison'!$G:$G,$C44,'Paired Comparison'!$E:$E,"box001") -> 0.17527071 | I44: =H44-G44 -> -0.039356736 | J44: =IF(E44="higher",I44,-I44) -> 0.039356736 | K44: 0.027272727 | L44: -0.0058206891 | M44: 0.083553899 | N44: =COUNTIFS('Paired Comparison'!$A:$A,$B44,'Paired Comparison'!$G:$G,$C44,'Paired Comparison'!$E:$E,"box001",'Paired Comparison'!$M:$M,">0") -> 14 | O44: =COUNTIFS('Paired Comparison'!$A:$A,$B44,'Paired Comparison'!$G:$G,$C44,'Paired Comparison'!$E:$E,"box001",'Paired Comparison'!$M:$M,"<0") -> 4
... A60: BOX001_ALL_AFFECTED_21 | B60: corrected_vs_contaminated_g1 | C60: fall_flag | D60: Fall flag | E60: lower | F60: =COUNTIFS('Paired Comparison'!$A:$A,$B60,'Paired Comparison'!$G:$G,$C60,'Paired Comparison'!$E:$E,"box001") -> 21 | G60: =AVERAGEIFS('Paired Comparison'!$J:$J,'Paired Comparison'!$A:$A,$B60,'Paired Comparison'!$G:$G,$C60,'Paired Comparison'!$E:$E,"box001") -> 0.047619048 | H60: =AVERAGEIFS('Paired Comparison'!$K:$K,'Paired Comparison'!$A:$A,$B60,'Paired Comparison'!$G:$G,$C60,'Paired Comparison'!$E:$E,"box001") -> 0.047619048 | I60: =H60-G60 -> 0 | J60: =IF(E60="higher",I60,-I60) -> 0 | K60: 0 | L60: 0 | M60: 0 | N60: =COUNTIFS('Paired Comparison'!$A:$A,$B60,'Paired Comparison'!$G:$G,$C60,'Paired Comparison'!$E:$E,"box001",'Paired Comparison'!$M:$M,">0") -> 0 | O60: =COUNTIFS('Paired Comparison'!$A:$A,$B60,'Paired Comparison'!$G:$G,$C60,'Paired Comparison'!$E:$E,"box001",'Paired Comparison'!$M:$M,"<0") -> 0
A61: BOX001_PRIMARY_20 | B61: corrected_vs_prg | C61: track_obj_z_abs_err_cm_mean | D61: Object z MAE (cm) | E61: lower | F61: =COUNTIFS('Paired Comparison'!$A:$A,$B61,'Paired Comparison'!$G:$G,$C61,'Paired Comparison'!$E:$E,"box001",'Paired Comparison'!$F:$F,TRUE()) -> 20 | G61: =AVERAGEIFS('Paired Comparison'!$J:$J,'Paired Comparison'!$A:$A,$B61,'Paired Comparison'!$G:$G,$C61,'Paired Comparison'!$E:$E,"box001",'Paired Comparison'!$F:$F,TRUE()) -> 4.7911164 | H61: =AVERAGEIFS('Paired Comparison'!$K:$K,'Paired Comparison'!$A:$A,$B61,'Paired Comparison'!$G:$G,$C61,'Paired Comparison'!$E:$E,"box001",'Paired Comparison'!$F:$F,TRUE()) -> 3.1501502 | I61: =H61-G61 -> -1.6409663 | J61: =IF(E61="higher",I61,-I61) -> 1.6409663 | K61: 1.6171308 | L61: 1.266534 | M61: 2.0129527 | N61: =COUNTIFS('Paired Comparison'!$A:$A,$B61,'Paired Comparison'!$G:$G,$C61,'Paired Comparison'!$E:$E,"box001",'Paired Comparison'!$F:$F,TRUE(),'Paired Comparison'!$M:$M,">0") -> 20 | O61: =COUNTIFS('Paired Comparison'!$A:$A,$B61,'Paired Comparison'!$G:$G,$C61,'Paired Comparison'!$E:$E,"box001",'Paired Comparison'!$F:$F,TRUE(),'Paired Comparison'!$M:$M,"<0") -> 0
A62: BOX001_PRIMARY_20 | B62: corrected_vs_prg | C62: track_obj_pos_err_cm_mean | D62: Object 3D position error (cm) | E62: lower | F62: =COUNTIFS('Paired Comparison'!$A:$A,$B62,'Paired Comparison'!$G:$G,$C62,'Paired Comparison'!$E:$E,"box001",'Paired Comparison'!$F:$F,TRUE()) -> 20 | G62: =AVERAGEIFS('Paired Comparison'!$J:$J,'Paired Comparison'!$A:$A,$B62,'Paired Comparison'!$G:$G,$C62,'Paired Comparison'!$E:$E,"box001",'Paired Comparison'!$F:$F,TRUE()) -> 11.024351 | H62: =AVERAGEIFS('Paired Comparison'!$K:$K,'Paired Comparison'!$A:$A,$B62,'Paired Comparison'!$G:$G,$C62,'Paired Comparison'!$E:$E,"box001",'Paired Comparison'!$F:$F,TRUE()) -> 9.4733398 | I62: =H62-G62 -> -1.5510117 | J62: =IF(E62="higher",I62,-I62) -> 1.5510117 | K62: 1.1781177 | L62: 0.75461002 | M62: 2.3945333 | N62: =COUNTIFS('Paired Comparison'!$A:$A,$B62,'Paired Comparison'!$G:$G,$C62,'Paired Comparison'!$E:$E,"box001",'Paired Comparison'!$F:$F,TRUE(),'Paired Comparison'!$M:$M,">0") -> 15 | O62: =COUNTIFS('Paired Comparison'!$A:$A,$B62,'Paired Comparison'!$G:$G,$C62,'Paired Comparison'!$E:$E,"box001",'Paired Comparison'!$F:$F,TRUE(),'Paired Comparison'!$M:$M,"<0") -> 5
A63: BOX001_PRIMARY_20 | B63: corrected_vs_prg | C63: track_obj_ori_err_deg_mean | D63: Object orientation error (deg) | E63: lower | F63: =COUNTIFS('Paired Comparison'!$A:$A,$B63,'Paired Comparison'!$G:$G,$C63,'Paired Comparison'!$E:$E,"box001",'Paired Comparison'!$F:$F,TRUE()) -> 20 | G63: =AVERAGEIFS('Paired Comparison'!$J:$J,'Paired Comparison'!$A:$A,$B63,'Paired Comparison'!$G:$G,$C63,'Paired Comparison'!$E:$E,"box001",'Paired Comparison'!$F:$F,TRUE()) -> 6.0756127 | H63: =AVERAGEIFS('Paired Comparison'!$K:$K,'Paired Comparison'!$A:$A,$B63,'Paired Comparison'!$G:$G,$C63,'Paired Comparison'!$E:$E,"box001",'Paired Comparison'!$F:$F,TRUE()) -> 5.2587384 | I63: =H63-G63 -> -0.81687437 | J63: =IF(E63="higher",I63,-I63) -> 0.81687437 | K63: 0.64751634 | L63: 0.22632164 | M63: 1.3990026 | N63: =COUNTIFS('Paired Comparison'!$A:$A,$B63,'Paired Comparison'!$G:$G,$C63,'Paired Comparison'!$E:$E,"box001",'Paired Comparison'!$F:$F,TRUE(),'Paired Comparison'!$M:$M,">0") -> 15 | O63: =COUNTIFS('Paired Comparison'!$A:$A,$B63,'Paired Comparison'!$G:$G,$C63,'Paired Comparison'!$E:$E,"box001",'Paired Comparison'!$F:$F,TRUE(),'Paired Comparison'!$M:$M,"<0") -> 5
A64: BOX001_PRIMARY_20 | B64: corrected_vs_prg | C64: body_z_err_p95_m | D64: Body z error p95 (m) | E64: lower | F64: =COUNTIFS('Paired Comparison'!$A:$A,$B64,'Paired Comparison'!$G:$G,$C64,'Paired Comparison'!$E:$E,"box001",'Paired Comparison'!$F:$F,TRUE()) -> 20 | G64: =AVERAGEIFS('Paired Comparison'!$J:$J,'Paired Comparison'!$A:$A,$B64,'Paired Comparison'!$G:$G,$C64,'Paired Comparison'!$E:$E,"box001",'Paired Comparison'!$F:$F,TRUE()) -> 0.083167981 | H64: =AVERAGEIFS('Paired Comparison'!$K:$K,'Paired Comparison'!$A:$A,$B64,'Paired Comparison'!$G:$G,$C64,'Paired Comparison'!$E:$E,"box001",'Paired Comparison'!$F:$F,TRUE()) -> 0.068736226 | I64: =H64-G64 -> -0.014431756 | J64: =IF(E64="higher",I64,-I64) -> 0.014431756 | K64: 0.013655831 | L64: 0.0090112804 | M64: 0.020154441 | N64: =COUNTIFS('Paired Comparison'!$A:$A,$B64,'Paired Comparison'!$G:$G,$C64,'Paired Comparison'!$E:$E,"box001",'Paired Comparison'!$F:$F,TRUE(),'Paired Comparison'!$M:$M,">0") -> 17 | O64: =COUNTIFS('Paired Comparison'!$A:$A,$B64,'Paired Comparison'!$G:$G,$C64,'Paired Comparison'!$E:$E,"box001",'Paired Comparison'!$F:$F,TRUE(),'Paired Comparison'!$M:$M,"<0") -> 3
A65: BOX001_PRIMARY_20 | B65: corrected_vs_prg | C65: track_root_pos_err_cm_mean | D65: Body/root position error (cm) | E65: lower | F65: =COUNTIFS('Paired Comparison'!$A:$A,$B65,'Paired Comparison'!$G:$G,$C65,'Paired Comparison'!$E:$E,"box001",'Paired Comparison'!$F:$F,TRUE()) -> 20 | G65: =AVERAGEIFS('Paired Comparison'!$J:$J,'Paired Comparison'!$A:$A,$B65,'Paired Comparison'!$G:$G,$C65,'Paired Comparison'!$E:$E,"box001",'Paired Comparison'!$F:$F,TRUE()) -> 16.216997 | H65: =AVERAGEIFS('Paired Comparison'!$K:$K,'Paired Comparison'!$A:$A,$B65,'Paired Comparison'!$G:$G,$C65,'Paired Comparison'!$E:$E,"box001",'Paired Comparison'!$F:$F,TRUE()) -> 16.486598 | I65: =H65-G65 -> 0.26960123 | J65: =IF(E65="higher",I65,-I65) -> -0.26960123 | K65: -1.0486487 | L65: -1.9273485 | M65: 1.4733526 | N65: =COUNTIFS('Paired Comparison'!$A:$A,$B65,'Paired Comparison'!$G:$G,$C65,'Paired Comparison'!$E:$E,"box001",'Paired Comparison'!$F:$F,TRUE(),'Paired Comparison'!$M:$M,">0") -> 9 | O65: =COUNTIFS('Paired Comparison'!$A:$A,$B65,'Paired Comparison'!$G:$G,$C65,'Paired Comparison'!$E:$E,"box001",'Paired Comparison'!$F:$F,TRUE(),'Paired Comparison'!$M:$M,"<0") -> 11
A66: BOX001_PRIMARY_20 | B66: corrected_vs_prg | C66: track_root_ori_err_deg_mean | D66: Body/root orientation error (deg) | E66: lower | F66: =COUNTIFS('Paired Comparison'!$A:$A,$B66,'Paired Comparison'!$G:$G,$C66,'Paired Comparison'!$E:$E,"box001",'Paired Comparison'!$F:$F,TRUE()) -> 20 | G66: =AVERAGEIFS('Paired Comparison'!$J:$J,'Paired Comparison'!$A:$A,$B66,'Paired Comparison'!$G:$G,$C66,'Paired Comparison'!$E:$E,"box001",'Paired Comparison'!$F:$F,TRUE()) -> 9.9014094 | H66: =AVERAGEIFS('Paired Comparison'!$K:$K,'Paired Comparison'!$A:$A,$B66,'Paired Comparison'!$G:$G,$C66,'Paired Comparison'!$E:$E,"box001",'Paired Comparison'!$F:$F,TRUE()) -> 8.7580042 | I66: =H66-G66 -> -1.1434052 | J66: =IF(E66="higher",I66,-I66) -> 1.1434052 | K66: 0.51023898 | L66: -0.059949455 | M66: 2.5403486 | N66: =COUNTIFS('Paired Comparison'!$A:$A,$B66,'Paired Comparison'!$G:$G,$C66,'Paired Comparison'!$E:$E,"box001",'Paired Comparison'!$F:$F,TRUE(),'Paired Comparison'!$M:$M,">0") -> 13 | O66: =COUNTIFS('Paired Comparison'!$A:$A,$B66,'Paired Comparison'!$G:$G,$C66,'Paired Comparison'!$E:$E,"box001",'Paired Comparison'!$F:$F,TRUE(),'Paired Comparison'!$M:$M,"<0") -> 7
A67: BOX001_PRIMARY_20 | B67: corrected_vs_prg | C67: track_eef_pos_err_cm_mean | D67: Combined hand position error (cm) | E67: lower | F67: =COUNTIFS('Paired Comparison'!$A:$A,$B67,'Paired Comparison'!$G:$G,$C67,'Paired Comparison'!$E:$E,"box001",'Paired Comparison'!$F:$F,TRUE()) -> 20 | G67: =AVERAGEIFS('Paired Comparison'!$J:$J,'Paired Comparison'!$A:$A,$B67,'Paired Comparison'!$G:$G,$C67,'Paired Comparison'!$E:$E,"box001",'Paired Comparison'!$F:$F,TRUE()) -> 16.004158 | H67: =AVERAGEIFS('Paired Comparison'!$K:$K,'Paired Comparison'!$A:$A,$B67,'Paired Comparison'!$G:$G,$C67,'Paired Comparison'!$E:$E,"box001",'Paired Comparison'!$F:$F,TRUE()) -> 15.734812 | I67: =H67-G67 -> -0.26934655 | J67: =IF(E67="higher",I67,-I67) -> 0.26934655 | K67: -0.87223837 | L67: -1.1507785 | M67: 1.8570812 | N67: =COUNTIFS('Paired Comparison'!$A:$A,$B67,'Paired Comparison'!$G:$G,$C67,'Paired Comparison'!$E:$E,"box001",'Paired Comparison'!$F:$F,TRUE(),'Paired Comparison'!$M:$M,">0") -> 9 | O67: =COUNTIFS('Paired Comparison'!$A:$A,$B67,'Paired Comparison'!$G:$G,$C67,'Paired Comparison'!$E:$E,"box001",'Paired Comparison'!$F:$F,TRUE(),'Paired Comparison'!$M:$M,"<0") -> 11
A68: BOX001_PRIMARY_20 | B68: corrected_vs_prg | C68: track_eef_ori_err_deg_mean | D68: Combined hand orientation error (deg) | E68: lower | F68: =COUNTIFS('Paired Comparison'!$A:$A,$B68,'Paired Comparison'!$G:$G,$C68,'Paired Comparison'!$E:$E,"box001",'Paired Comparison'!$F:$F,TRUE()) -> 20 | G68: =AVERAGEIFS('Paired Comparison'!$J:$J,'Paired Comparison'!$A:$A,$B68,'Paired Comparison'!$G:$G,$C68,'Paired Comparison'!$E:$E,"box001",'Paired Comparison'!$F:$F,TRUE()) -> 18.556519 | H68: =AVERAGEIFS('Paired Comparison'!$K:$K,'Paired Comparison'!$A:$A,$B68,'Paired Comparison'!$G:$G,$C68,'Paired Comparison'!$E:$E,"box001",'Paired Comparison'!$F:$F,TRUE()) -> 17.864376 | I68: =H68-G68 -> -0.69214347 | J68: =IF(E68="higher",I68,-I68) -> 0.69214347 | K68: 0.36313839 | L68: -0.55907738 | M68: 2.041943 | N68: =COUNTIFS('Paired Comparison'!$A:$A,$B68,'Paired Comparison'!$G:$G,$C68,'Paired Comparison'!$E:$E,"box001",'Paired Comparison'!$F:$F,TRUE(),'Paired Comparison'!$M:$M,">0") -> 13 | O68: =COUNTIFS('Paired Comparison'!$A:$A,$B68,'Paired Comparison'!$G:$G,$C68,'Paired Comparison'!$E:$E,"box001",'Paired Comparison'!$F:$F,TRUE(),'Paired Comparison'!$M:$M,"<0") -> 7
A69: BOX001_PRIMARY_20 | B69: corrected_vs_prg | C69: hand_object_physics_contact_3mm_in_mask_frac | D69: 3 mm contact fraction | E69: higher | F69: =COUNTIFS('Paired Comparison'!$A:$A,$B69,'Paired Comparison'!$G:$G,$C69,'Paired Comparison'!$E:$E,"box001",'Paired Comparison'!$F:$F,TRUE()) -> 20 | G69: =AVERAGEIFS('Paired Comparison'!$J:$J,'Paired Comparison'!$A:$A,$B69,'Paired Comparison'!$G:$G,$C69,'Paired Comparison'!$E:$E,"box001",'Paired Comparison'!$F:$F,TRUE()) -> 0.51522104 | H69: =AVERAGEIFS('Paired Comparison'!$K:$K,'Paired Comparison'!$A:$A,$B69,'Paired Comparison'!$G:$G,$C69,'Paired Comparison'!$E:$E,"box001",'Paired Comparison'!$F:$F,TRUE()) -> 0.57190365 | I69: =H69-G69 -> 0.056682609 | J69: =IF(E69="higher",I69,-I69) -> 0.056682609 | K69: 0.063938619 | L69: 0.010379832 | M69: 0.103847 | N69: =COUNTIFS('Paired Comparison'!$A:$A,$B69,'Paired Comparison'!$G:$G,$C69,'Paired Comparison'!$E:$E,"box001",'Paired Comparison'!$F:$F,TRUE(),'Paired Comparison'!$M:$M,">0") -> 15 | O69: =COUNTIFS('Paired Comparison'!$A:$A,$B69,'Paired Comparison'!$G:$G,$C69,'Paired Comparison'!$E:$E,"box001",'Paired Comparison'!$F:$F,TRUE(),'Paired Comparison'!$M:$M,"<0") -> 4
A70: BOX001_PRIMARY_20 | B70: corrected_vs_prg | C70: hand_object_physics_contact_in_mask_frac | D70: Raw contact fraction | E70: higher | F70: =COUNTIFS('Paired Comparison'!$A:$A,$B70,'Paired Comparison'!$G:$G,$C70,'Paired Comparison'!$E:$E,"box001",'Paired Comparison'!$F:$F,TRUE()) -> 20 | G70: =AVERAGEIFS('Paired Comparison'!$J:$J,'Paired Comparison'!$A:$A,$B70,'Paired Comparison'!$G:$G,$C70,'Paired Comparison'!$E:$E,"box001",'Paired Comparison'!$F:$F,TRUE()) -> 0.83987087 | H70: =AVERAGEIFS('Paired Comparison'!$K:$K,'Paired Comparison'!$A:$A,$B70,'Paired Comparison'!$G:$G,$C70,'Paired Comparison'!$E:$E,"box001",'Paired Comparison'!$F:$F,TRUE()) -> 0.82593789 | I70: =H70-G70 -> -0.013932979 | J70: =IF(E70="higher",I70,-I70) -> -0.013932979 | K70: 0 | L70: -0.055385322 | M70: 0.020091313 | N70: =COUNTIFS('Paired Comparison'!$A:$A,$B70,'Paired Comparison'!$G:$G,$C70,'Paired Comparison'!$E:$E,"box001",'Paired Comparison'!$F:$F,TRUE(),'Paired Comparison'!$M:$M,">0") -> 7 | O70: =COUNTIFS('Paired Comparison'!$A:$A,$B70,'Paired Comparison'!$G:$G,$C70,'Paired Comparison'!$E:$E,"box001",'Paired Comparison'!$F:$F,TRUE(),'Paired Comparison'!$M:$M,"<0") -> 8
A71: BOX001_PRIMARY_20 | B71: corrected_vs_prg | C71: hand_object_release_false_contact_3mm_frac | D71: False release fraction | E71: lower | F71: =COUNTIFS('Paired Comparison'!$A:$A,$B71,'Paired Comparison'!$G:$G,$C71,'Paired Comparison'!$E:$E,"box001",'Paired Comparison'!$F:$F,TRUE()) -> 20 | G71: =AVERAGEIFS('Paired Comparison'!$J:$J,'Paired Comparison'!$A:$A,$B71,'Paired Comparison'!$G:$G,$C71,'Paired Comparison'!$E:$E,"box001",'Paired Comparison'!$F:$F,TRUE()) -> 0.13224159 | H71: =AVERAGEIFS('Paired Comparison'!$K:$K,'Paired Comparison'!$A:$A,$B71,'Paired Comparison'!$G:$G,$C71,'Paired Comparison'!$E:$E,"box001",'Paired Comparison'!$F:$F,TRUE()) -> 0.13230114 | I71: =H71-G71 -> 5.9554185e-05 | J71: =IF(E71="higher",I71,-I71) -> -5.9554185e-05 | K71: 0 | L71: -0.06650455 | M71: 0.049498083 | N71: =COUNTIFS('Paired Comparison'!$A:$A,$B71,'Paired Comparison'!$G:$G,$C71,'Paired Comparison'!$E:$E,"box001",'Paired Comparison'!$F:$F,TRUE(),'Paired Comparison'!$M:$M,">0") -> 9 | O71: =COUNTIFS('Paired Comparison'!$A:$A,$B71,'Paired Comparison'!$G:$G,$C71,'Paired Comparison'!$E:$E,"box001",'Paired Comparison'!$F:$F,TRUE(),'Paired Comparison'!$M:$M,"<0") -> 6
...

Sheet 12-Gate
A1: Twelve-gate migrations
A2: Every case and gate is shown for corrected G1 against PRG and contaminated G1.
A4: Comparison | B4: Baseline arm | C4: Candidate arm | D4: Case | E4: Object | F4: Gate | G4: Baseline pass | H4: Candidate pass | I4: Migration
A5: corrected_vs_prg | B5: PRG | C5: G1 corrected | D5: box001_20231003_2_041_p1 | E5: box001 | F5: fall | G5: =TRUE() -> TRUE | H5: =TRUE() -> TRUE | I5: =IF(AND(G5,H5),"PASS_TO_PASS",IF(G5,"PASS_TO_FAIL",IF(H5,"FAIL_TO_PASS","FAIL_TO_FAIL"))) -> PASS_TO_PASS
A6: corrected_vs_prg | B6: PRG | C6: G1 corrected | D6: box001_20231003_2_041_p1 | E6: box001 | F6: body_z | G6: =TRUE() -> TRUE | H6: =TRUE() -> TRUE | I6: =IF(AND(G6,H6),"PASS_TO_PASS",IF(G6,"PASS_TO_FAIL",IF(H6,"FAIL_TO_PASS","FAIL_TO_FAIL"))) -> PASS_TO_PASS
A7: corrected_vs_prg | B7: PRG | C7: G1 corrected | D7: box001_20231003_2_041_p1 | E7: box001 | F7: contact | G7: =TRUE() -> TRUE | H7: =TRUE() -> TRUE | I7: =IF(AND(G7,H7),"PASS_TO_PASS",IF(G7,"PASS_TO_FAIL",IF(H7,"FAIL_TO_PASS","FAIL_TO_FAIL"))) -> PASS_TO_PASS
A8: corrected_vs_prg | B8: PRG | C8: G1 corrected | D8: box001_20231003_2_041_p1 | E8: box001 | F8: release | G8: =TRUE() -> TRUE | H8: =TRUE() -> TRUE | I8: =IF(AND(G8,H8),"PASS_TO_PASS",IF(G8,"PASS_TO_FAIL",IF(H8,"FAIL_TO_PASS","FAIL_TO_FAIL"))) -> PASS_TO_PASS
A9: corrected_vs_prg | B9: PRG | C9: G1 corrected | D9: box001_20231003_2_041_p1 | E9: box001 | F9: hand_penetration | G9: =TRUE() -> TRUE | H9: =TRUE() -> TRUE | I9: =IF(AND(G9,H9),"PASS_TO_PASS",IF(G9,"PASS_TO_FAIL",IF(H9,"FAIL_TO_PASS","FAIL_TO_FAIL"))) -> PASS_TO_PASS
A10: corrected_vs_prg | B10: PRG | C10: G1 corrected | D10: box001_20231003_2_041_p1 | E10: box001 | F10: lower_body | G10: =TRUE() -> TRUE | H10: =TRUE() -> TRUE | I10: =IF(AND(G10,H10),"PASS_TO_PASS",IF(G10,"PASS_TO_FAIL",IF(H10,"FAIL_TO_PASS","FAIL_TO_FAIL"))) -> PASS_TO_PASS
A11: corrected_vs_prg | B11: PRG | C11: G1 corrected | D11: box001_20231003_2_041_p1 | E11: box001 | F11: root_pos | G11: =TRUE() -> TRUE | H11: =TRUE() -> TRUE | I11: =IF(AND(G11,H11),"PASS_TO_PASS",IF(G11,"PASS_TO_FAIL",IF(H11,"FAIL_TO_PASS","FAIL_TO_FAIL"))) -> PASS_TO_PASS
A12: corrected_vs_prg | B12: PRG | C12: G1 corrected | D12: box001_20231003_2_041_p1 | E12: box001 | F12: root_ori | G12: =TRUE() -> TRUE | H12: =TRUE() -> TRUE | I12: =IF(AND(G12,H12),"PASS_TO_PASS",IF(G12,"PASS_TO_FAIL",IF(H12,"FAIL_TO_PASS","FAIL_TO_FAIL"))) -> PASS_TO_PASS
A13: corrected_vs_prg | B13: PRG | C13: G1 corrected | D13: box001_20231003_2_041_p1 | E13: box001 | F13: hand_pos | G13: =TRUE() -> TRUE | H13: =TRUE() -> TRUE | I13: =IF(AND(G13,H13),"PASS_TO_PASS",IF(G13,"PASS_TO_FAIL",IF(H13,"FAIL_TO_PASS","FAIL_TO_FAIL"))) -> PASS_TO_PASS
A14: corrected_vs_prg | B14: PRG | C14: G1 corrected | D14: box001_20231003_2_041_p1 | E14: box001 | F14: hand_ori | G14: =FALSE() -> FALSE | H14: =TRUE() -> TRUE | I14: =IF(AND(G14,H14),"PASS_TO_PASS",IF(G14,"PASS_TO_FAIL",IF(H14,"FAIL_TO_PASS","FAIL_TO_FAIL"))) -> FAIL_TO_PASS
A15: corrected_vs_prg | B15: PRG | C15: G1 corrected | D15: box001_20231003_2_041_p1 | E15: box001 | F15: object_pos | G15: =TRUE() -> TRUE | H15: =TRUE() -> TRUE | I15: =IF(AND(G15,H15),"PASS_TO_PASS",IF(G15,"PASS_TO_FAIL",IF(H15,"FAIL_TO_PASS","FAIL_TO_FAIL"))) -> PASS_TO_PASS
A16: corrected_vs_prg | B16: PRG | C16: G1 corrected | D16: box001_20231003_2_041_p1 | E16: box001 | F16: object_ori | G16: =TRUE() -> TRUE | H16: =TRUE() -> TRUE | I16: =IF(AND(G16,H16),"PASS_TO_PASS",IF(G16,"PASS_TO_FAIL",IF(H16,"FAIL_TO_PASS","FAIL_TO_FAIL"))) -> PASS_TO_PASS
A17: corrected_vs_contaminated_g1 | B17: G1 contaminated | C17: G1 corrected | D17: box001_20231003_2_041_p1 | E17: box001 | F17: fall | G17: =TRUE() -> TRUE | H17: =TRUE() -> TRUE | I17: =IF(AND(G17,H17),"PASS_TO_PASS",IF(G17,"PASS_TO_FAIL",IF(H17,"FAIL_TO_PASS","FAIL_TO_FAIL"))) -> PASS_TO_PASS
A18: corrected_vs_contaminated_g1 | B18: G1 contaminated | C18: G1 corrected | D18: box001_20231003_2_041_p1 | E18: box001 | F18: body_z | G18: =TRUE() -> TRUE | H18: =TRUE() -> TRUE | I18: =IF(AND(G18,H18),"PASS_TO_PASS",IF(G18,"PASS_TO_FAIL",IF(H18,"FAIL_TO_PASS","FAIL_TO_FAIL"))) -> PASS_TO_PASS
A19: corrected_vs_contaminated_g1 | B19: G1 contaminated | C19: G1 corrected | D19: box001_20231003_2_041_p1 | E19: box001 | F19: contact | G19: =TRUE() -> TRUE | H19: =TRUE() -> TRUE | I19: =IF(AND(G19,H19),"PASS_TO_PASS",IF(G19,"PASS_TO_FAIL",IF(H19,"FAIL_TO_PASS","FAIL_TO_FAIL"))) -> PASS_TO_PASS
A20: corrected_vs_contaminated_g1 | B20: G1 contaminated | C20: G1 corrected | D20: box001_20231003_2_041_p1 | E20: box001 | F20: release | G20: =TRUE() -> TRUE | H20: =TRUE() -> TRUE | I20: =IF(AND(G20,H20),"PASS_TO_PASS",IF(G20,"PASS_TO_FAIL",IF(H20,"FAIL_TO_PASS","FAIL_TO_FAIL"))) -> PASS_TO_PASS
A21: corrected_vs_contaminated_g1 | B21: G1 contaminated | C21: G1 corrected | D21: box001_20231003_2_041_p1 | E21: box001 | F21: hand_penetration | G21: =TRUE() -> TRUE | H21: =TRUE() -> TRUE | I21: =IF(AND(G21,H21),"PASS_TO_PASS",IF(G21,"PASS_TO_FAIL",IF(H21,"FAIL_TO_PASS","FAIL_TO_FAIL"))) -> PASS_TO_PASS
A22: corrected_vs_contaminated_g1 | B22: G1 contaminated | C22: G1 corrected | D22: box001_20231003_2_041_p1 | E22: box001 | F22: lower_body | G22: =TRUE() -> TRUE | H22: =TRUE() -> TRUE | I22: =IF(AND(G22,H22),"PASS_TO_PASS",IF(G22,"PASS_TO_FAIL",IF(H22,"FAIL_TO_PASS","FAIL_TO_FAIL"))) -> PASS_TO_PASS
A23: corrected_vs_contaminated_g1 | B23: G1 contaminated | C23: G1 corrected | D23: box001_20231003_2_041_p1 | E23: box001 | F23: root_pos | G23: =TRUE() -> TRUE | H23: =TRUE() -> TRUE | I23: =IF(AND(G23,H23),"PASS_TO_PASS",IF(G23,"PASS_TO_FAIL",IF(H23,"FAIL_TO_PASS","FAIL_TO_FAIL"))) -> PASS_TO_PASS
A24: corrected_vs_contaminated_g1 | B24: G1 contaminated | C24: G1 corrected | D24: box001_20231003_2_041_p1 | E24: box001 | F24: root_ori | G24: =TRUE() -> TRUE | H24: =TRUE() -> TRUE | I24: =IF(AND(G24,H24),"PASS_TO_PASS",IF(G24,"PASS_TO_FAIL",IF(H24,"FAIL_TO_PASS","FAIL_TO_FAIL"))) -> PASS_TO_PASS
A25: corrected_vs_contaminated_g1 | B25: G1 contaminated | C25: G1 corrected | D25: box001_20231003_2_041_p1 | E25: box001 | F25: hand_pos | G25: =TRUE() -> TRUE | H25: =TRUE() -> TRUE | I25: =IF(AND(G25,H25),"PASS_TO_PASS",IF(G25,"PASS_TO_FAIL",IF(H25,"FAIL_TO_PASS","FAIL_TO_FAIL"))) -> PASS_TO_PASS
A26: corrected_vs_contaminated_g1 | B26: G1 contaminated | C26: G1 corrected | D26: box001_20231003_2_041_p1 | E26: box001 | F26: hand_ori | G26: =FALSE() -> FALSE | H26: =TRUE() -> TRUE | I26: =IF(AND(G26,H26),"PASS_TO_PASS",IF(G26,"PASS_TO_FAIL",IF(H26,"FAIL_TO_PASS","FAIL_TO_FAIL"))) -> FAIL_TO_PASS
A27: corrected_vs_contaminated_g1 | B27: G1 contaminated | C27: G1 corrected | D27: box001_20231003_2_041_p1 | E27: box001 | F27: object_pos | G27: =TRUE() -> TRUE | H27: =TRUE() -> TRUE | I27: =IF(AND(G27,H27),"PASS_TO_PASS",IF(G27,"PASS_TO_FAIL",IF(H27,"FAIL_TO_PASS","FAIL_TO_FAIL"))) -> PASS_TO_PASS
A28: corrected_vs_contaminated_g1 | B28: G1 contaminated | C28: G1 corrected | D28: box001_20231003_2_041_p1 | E28: box001 | F28: object_ori | G28: =FALSE() -> FALSE | H28: =TRUE() -> TRUE | I28: =IF(AND(G28,H28),"PASS_TO_PASS",IF(G28,"PASS_TO_FAIL",IF(H28,"FAIL_TO_PASS","FAIL_TO_FAIL"))) -> FAIL_TO_PASS
A29: corrected_vs_prg | B29: PRG | C29: G1 corrected | D29: box001_20231003_1_039_p1 | E29: box001 | F29: fall | G29: =TRUE() -> TRUE | H29: =TRUE() -> TRUE | I29: =IF(AND(G29,H29),"PASS_TO_PASS",IF(G29,"PASS_TO_FAIL",IF(H29,"FAIL_TO_PASS","FAIL_TO_FAIL"))) -> PASS_TO_PASS
A30: corrected_vs_prg | B30: PRG | C30: G1 corrected | D30: box001_20231003_1_039_p1 | E30: box001 | F30: body_z | G30: =TRUE() -> TRUE | H30: =TRUE() -> TRUE | I30: =IF(AND(G30,H30),"PASS_TO_PASS",IF(G30,"PASS_TO_FAIL",IF(H30,"FAIL_TO_PASS","FAIL_TO_FAIL"))) -> PASS_TO_PASS
A31: corrected_vs_prg | B31: PRG | C31: G1 corrected | D31: box001_20231003_1_039_p1 | E31: box001 | F31: contact | G31: =TRUE() -> TRUE | H31: =TRUE() -> TRUE | I31: =IF(AND(G31,H31),"PASS_TO_PASS",IF(G31,"PASS_TO_FAIL",IF(H31,"FAIL_TO_PASS","FAIL_TO_FAIL"))) -> PASS_TO_PASS
A32: corrected_vs_prg | B32: PRG | C32: G1 corrected | D32: box001_20231003_1_039_p1 | E32: box001 | F32: release | G32: =TRUE() -> TRUE | H32: =TRUE() -> TRUE | I32: =IF(AND(G32,H32),"PASS_TO_PASS",IF(G32,"PASS_TO_FAIL",IF(H32,"FAIL_TO_PASS","FAIL_TO_FAIL"))) -> PASS_TO_PASS
A33: corrected_vs_prg | B33: PRG | C33: G1 corrected | D33: box001_20231003_1_039_p1 | E33: box001 | F33: hand_penetration | G33: =TRUE() -> TRUE | H33: =TRUE() -> TRUE | I33: =IF(AND(G33,H33),"PASS_TO_PASS",IF(G33,"PASS_TO_FAIL",IF(H33,"FAIL_TO_PASS","FAIL_TO_FAIL"))) -> PASS_TO_PASS
A34: corrected_vs_prg | B34: PRG | C34: G1 corrected | D34: box001_20231003_1_039_p1 | E34: box001 | F34: lower_body | G34: =TRUE() -> TRUE | H34: =TRUE() -> TRUE | I34: =IF(AND(G34,H34),"PASS_TO_PASS",IF(G34,"PASS_TO_FAIL",IF(H34,"FAIL_TO_PASS","FAIL_TO_FAIL"))) -> PASS_TO_PASS
A35: corrected_vs_prg | B35: PRG | C35: G1 corrected | D35: box001_20231003_1_039_p1 | E35: box001 | F35: root_pos | G35: =TRUE() -> TRUE | H35: =TRUE() -> TRUE | I35: =IF(AND(G35,H35),"PASS_TO_PASS",IF(G35,"PASS_TO_FAIL",IF(H35,"FAIL_TO_PASS","FAIL_TO_FAIL"))) -> PASS_TO_PASS
A36: corrected_vs_prg | B36: PRG | C36: G1 corrected | D36: box001_20231003_1_039_p1 | E36: box001 | F36: root_ori | G36: =TRUE() -> TRUE | H36: =TRUE() -> TRUE | I36: =IF(AND(G36,H36),"PASS_TO_PASS",IF(G36,"PASS_TO_FAIL",IF(H36,"FAIL_TO_PASS","FAIL_TO_FAIL"))) -> PASS_TO_PASS
A37: corrected_vs_prg | B37: PRG | C37: G1 corrected | D37: box001_20231003_1_039_p1 | E37: box001 | F37: hand_pos | G37: =TRUE() -> TRUE | H37: =TRUE() -> TRUE | I37: =IF(AND(G37,H37),"PASS_TO_PASS",IF(G37,"PASS_TO_FAIL",IF(H37,"FAIL_TO_PASS","FAIL_TO_FAIL"))) -> PASS_TO_PASS
